Workbook

Sheet Sheet1
A1: 贷款编号 | B1: 贷款金额 | C1: 产品名称 | D1: 商户 | E1: 门店 | F1: SA工号 | G1: SA姓名 | H1: SA状态 | I1: 区域经理工号 | J1: 区域经理名称 | K1: 区域经理助理工号 | L1: 区域经理助理名称 | M1: 区域名称 | N1: 高区名称 | O1: 城市名称 | P1: 大区名称 | Q1: 首次M2 | R1: 首次M3 | S1: 原产品名称
A2: 653102018110203082 | B2: 3800 | C2: 一般产品 | D2: 海口美兰贝肯通讯商店 | E2: 喀什市天地电动车超市 | F2: 13260049 | G2: 满正伯 | H2: 离职 | I2: 12190182 | J2: 李仕兴 | M2: 李仕兴团队 | N2: 邹垚睿团队 | O2: 新疆大区 | P2: 北区团队 | Q2: 1 | R2: 0 | S2: =IFERROR(VLOOKUP(C2,Sheet2!B:E,4,0),C2) -> 一般产品
A3: 522702018110103593 | B3: 3498 | C3: 优惠产品A | D3: 西安高新区兴和电子产品经销部 | E3: 罗甸县边阳镇钰涵科技通讯店 | F3: 08250232 | G3: 黄元梅 | H3: 在职 | I3: 23250401 | J3: 王永辉 | M3: 王永辉团队 | N3: 范光文团队 | O3: 贵州大区 | P3: 西区团队 | Q3: 1 | R3: 0 | S3: =IFERROR(VLOOKUP(C3,Sheet2!B:E,4,0),C3) -> 优惠产品
A4: 150802018110101345 | B4: 2799 | C4: 优惠产品A | D4: 西宁市城西区雅勤通讯设备经营部 | E4: 临河区伟国手机经销河港店 | F4: 12250763 | G4: 李勇 | H4: 在职 | I4: 12070026 | J4: 李刚刚 | M4: 李刚刚团队 | N4: 预留团队5 | O4: 内蒙古大区 | P4: 北区团队 | Q4: 1 | R4: 0 | S4: =IFERROR(VLOOKUP(C4,Sheet2!B:E,4,0),C4) -> 优惠产品
A5: 653102018110103150 | B5: 2800 | C5: 一般产品 | D5: 南昌高新技术产业开发区宇恒联合数码产品店 | E5: 喀什市搏锋电子产品经销部 | F5: 03120154 | G5: 陈丽萍 | H5: 在职 | I5: 13230011 | J5: 买吾拉尼·吐尔逊 | M5: 买吾拉尼·吐尔逊团队 | N5: 邹垚睿团队 | O5: 新疆大区 | P5: 北区团队 | Q5: 1 | R5: 0 | S5: =IFERROR(VLOOKUP(C5,Sheet2!B:E,4,0),C5) -> 一般产品
A6: 650102018110101860 | B6: 3600 | C6: 一般产品 | D6: 西安高新区兴和电子产品经销部 | E6: 乌鲁木齐潮客电子商务有限公司-火车西站安康路西巷信达通通讯店 | F6: 13230025 | G6: 马伟玲 | H6: 在职 | K6: 18250023 | M6: 预留（任永佳） | N6: 高骅团队 | O6: 新疆大区 | P6: 北区团队 | Q6: 1 | R6: 0 | S6: =IFERROR(VLOOKUP(C6,Sheet2!B:E,4,0),C6) -> 一般产品
A7: 520202018110102707 | B7: 2499 | C7: 优惠产品A | D7: 汇川区亨乐尔通讯经营部 | E7: 中国移动 | F7: 04160020 | G7: 段朋元 | H7: 离职 | I7: 26240029 | J7: 邹幸朋 | M7: 邹幸朋团队 | N7: 孙雷团队 | O7: 贵州大区 | P7: 西区团队 | Q7: 1 | R7: 0 | S7: =IFERROR(VLOOKUP(C7,Sheet2!B:E,4,0),C7) -> 优惠产品
A8: 654002018110202514 | B8: 2100 | C8: 一般产品 | D8: 海口美兰贝肯通讯商店 | E8: 霍城县网信春雷手机店 | F8: 02100023 | G8: 白进玉 | H8: 在职 | I8: 13120052 | J8: 马丽娜 | M8: 马丽娜团队 | N8: 陈香团队 | O8: 新疆大区 | P8: 北区团队 | Q8: 1 | R8: 0 | S8: =IFERROR(VLOOKUP(C8,Sheet2!B:E,4,0),C8) -> 一般产品
A9: 520102018110201457 | B9: 1799 | C9: 一般产品 | D9: 汇川区亨乐尔通讯经营部 | E9: 观山湖狗场琴红通讯个体户王仕中 | F9: 18080002 | G9: 任海 | H9: 在职 | I9: 02030001 | J9: 柏超 | M9: 柏超团队 | N9: 周鹏团队 | O9: 贵州大区 | P9: 西区团队 | Q9: 1 | R9: 0 | S9: =IFERROR(VLOOKUP(C9,Sheet2!B:E,4,0),C9) -> 一般产品
A10: 522702018110302195 | B10: 1599 | C10: 优惠产品A | D10: 西安高新区兴和电子产品经销部 | E10: 罗甸县铭星通讯店 | F10: 04100106 | G10: 邓久彪 | H10: 在职 | I10: 23250401 | J10: 王永辉 | M10: 王永辉团队 | N10: 范光文团队 | O10: 贵州大区 | P10: 西区团队 | Q10: 1 | R10: 0 | S10: =IFERROR(VLOOKUP(C10,Sheet2!B:E,4,0),C10) -> 优惠产品
A11: 652302018110101851 | B11: 3098 | C11: 一般产品 | D11: 海口美兰贝肯通讯商店 | E11: 昌吉市宏杨通讯器材经营部 | F11: 04230060 | G11: 戴玮 | H11: 在职 | I11: 08260079 | J11: 胡忠旺 | M11: 胡忠旺团队 | N11: 高骅团队 | O11: 新疆大区 | P11: 北区团队 | Q11: 1 | R11: 0 | S11: =IFERROR(VLOOKUP(C11,Sheet2!B:E,4,0),C11) -> 一般产品
A12: 522602018110302517 | B12: 3280 | C12: 优惠产品A | D12: 汇川区亨乐尔通讯经营部 | E12: 个体户何胜兰 | F12: 26080212 | G12: 周湖星 | H12: 在职 | K12: 24060011 | M12: 预留（夏峰瑞） | N12: 范光文团队 | O12: 贵州大区 | P12: 西区团队 | Q12: 1 | R12: 0 | S12: =IFERROR(VLOOKUP(C12,Sheet2!B:E,4,0),C12) -> 优惠产品
A13: 653102018110302176 | B13: 4000 | C13: 一般产品 | D13: 南昌高新技术产业开发区宇恒联合数码产品店 | E13: 岳普湖县热孜万古丽摩托车销售店 | F13: 01190016 | G13: 艾斯克尔·牙库甫 | H13: 在职 | I13: 17100016 | J13: 卿继蓬 | M13: 卿继蓬团队 | N13: 邹垚睿团队 | O13: 新疆大区 | P13: 北区团队 | Q13: 1 | R13: 0 | S13: =IFERROR(VLOOKUP(C13,Sheet2!B:E,4,0),C13) -> 一般产品
A14: 460102018110102852 | B14: 3498 | C14: 优惠产品B | D14: 海口美兰贝肯通讯商店 | E14: 海口美兰悟俱嘉通讯商行 | F14: 12230183 | G14: 刘文彬 | H14: 在职 | I14: 23170073 | J14: 王群斯 | M14: 王群斯团队 | N14: 方东迅团队 | O14: 海南大区 | P14: 南区团队 | Q14: 1 | R14: 0 | S14: =IFERROR(VLOOKUP(C14,Sheet2!B:E,4,0),C14) -> 优惠产品
A15: 540102018110103439 | B15: 1598 | C15: 一般产品 | D15: 汇川区亨乐尔通讯经营部 | E15: 星宇通讯色拉路店 | F15: 23250450 | G15: 王有琴 | H15: 在职 | I15: 19040037 | J15: 盛玬玛 | M15: 盛玬玛团队 | N15: 预留团队 | O15: 西藏大区 | P15: 直管团队 | Q15: 1 | R15: 0 | S15: =IFERROR(VLOOKUP(C15,Sheet2!B:E,4,0),C15) -> 一般产品
A16: 150802018110301874 | B16: 3498 | C16: 优惠产品A | D16: 西宁市城西区雅勤通讯设备经营部 | E16: 巴彦淖尔市临河区星运通讯二分店 | F16: 03250145 | G16: 曹宇 | H16: 在职 | I16: 12070026 | J16: 李刚刚 | M16: 李刚刚团队 | N16: 预留团队5 | O16: 内蒙古大区 | P16: 北区团队 | Q16: 1 | R16: 0 | S16: =IFERROR(VLOOKUP(C16,Sheet2!B:E,4,0),C16) -> 优惠产品
A17: 540102018110102497 | B17: 3800 | C17: 一般产品 | D17: 西宁市城西区雅勤通讯设备经营部 | E17: 贵尊摩托车行 | F17: 12080304 | G17: 罗华 | H17: 在职 | I17: 19040037 | J17: 盛玬玛 | M17: 盛玬玛团队 | N17: 预留团队 | O17: 西藏大区 | P17: 直管团队 | Q17: 1 | R17: 0 | S17: =IFERROR(VLOOKUP(C17,Sheet2!B:E,4,0),C17) -> 一般产品
A18: 654002018110201542 | B18: 4400 | C18: 一般产品 | D18: 海口美兰贝肯通讯商店 | E18: 霍城县赛合丽电动车维修部 | F18: 03060035 | G18: 陈凤凤 | H18: 离职 | I18: 13120052 | J18: 马丽娜 | M18: 马丽娜团队 | N18: 陈香团队 | O18: 新疆大区 | P18: 北区团队 | Q18: 1 | R18: 0 | S18: =IFERROR(VLOOKUP(C18,Sheet2!B:E,4,0),C18) -> 一般产品
A19: 653002018110302094 | B19: 1800 | C19: 一般产品 | D19: 南昌高新技术产业开发区宇恒联合数码产品店 | E19: 阿图什市祥瑞通讯店 | F19: 19100113 | G19: 孙静杰 | H19: 离职 | I19: 23160051 | J19: 吴鹏飞 | M19: 吴鹏飞团队 | N19: 邹垚睿团队 | O19: 新疆大区 | P19: 北区团队 | Q19: 1 | R19: 0 | S19: =IFERROR(VLOOKUP(C19,Sheet2!B:E,4,0),C19) -> 一般产品
A20: 653102018110302212 | B20: 5000 | C20: 一般产品 | D20: 南昌高新技术产业开发区宇恒联合数码产品店 | E20: 莎车县帕提明麦麦提电动车销售店 | F20: 20190037 | G20: 吐孙·麦麦提尼亚孜 | H20: 离职 | K20: 02110007 | M20: 预留（别克木尔扎·扎依尔） | N20: 邹垚睿团队 | O20: 新疆大区 | P20: 北区团队 | Q20: 1 | R20: 0 | S20: =IFERROR(VLOOKUP(C20,Sheet2!B:E,4,0),C20) -> 一般产品
A21: 652302018110302402 | B21: 1999 | C21: 一般产品 | D21: 海口美兰贝肯通讯商店 | E21: 昌吉市鑫鹏手机经销店 | F21: 25230061 | G21: 杨万鹏 | H21: 在职 | I21: 23250352 | J21: 武亚文 | M21: 武亚文团队 | N21: 高骅团队 | O21: 新疆大区 | P21: 北区团队 | Q21: 1 | R21: 0 | S21: =IFERROR(VLOOKUP(C21,Sheet2!B:E,4,0),C21) -> 一般产品
A22: 652102018110103206 | B22: 1400 | C22: 优惠产品A | D22: 海口美兰贝肯通讯商店 | E22: 高昌区玛雅克通讯店 | F22: 24240108 | G22: 徐孝 | H22: 离职 | I22: 19160015 | J22: 孙鹏翔 | M22: 孙鹏翔团队 | N22: 肖强团队 | O22: 新疆大区 | P22: 北区团队 | Q22: 1 | R22: 0 | S22: =IFERROR(VLOOKUP(C22,Sheet2!B:E,4,0),C22) -> 优惠产品
A23: 610102018110102503 | B23: 3980 | C23: 优惠产品B | D23: 汇川区亨乐尔通讯经营部 | E23: 健康路店 | F23: 24160016 | G23: 徐鹏超 | H23: 在职 | I23: 12250053 | J23: 林雅琼 | M23: 林雅琼团队 | N23: 预留团队4 | O23: 陕西大区 | P23: 西区团队 | Q23: 1 | R23: 0 | S23: =IFERROR(VLOOKUP(C23,Sheet2!B:E,4,0),C23) -> 优惠产品
A24: 654002018110203016 | B24: 4400 | C24: 一般产品 | D24: 海口美兰贝肯通讯商店 | E24: 霍城县大众家电超市 | F24: 03060035 | G24: 陈凤凤 | H24: 离职 | I24: 13120052 | J24: 马丽娜 | M24: 马丽娜团队 | N24: 陈香团队 | O24: 新疆大区 | P24: 北区团队 | Q24: 1 | R24: 0 | S24: =IFERROR(VLOOKUP(C24,Sheet2!B:E,4,0),C24) -> 一般产品
A25: 530102018110302166 | B25: 3000 | C25: 一般产品 | D25: 海口美兰贝肯通讯商店 | E25: 昆明市西山区动盟电动车经营部 | F25: 23020075 | G25: 王斌 | H25: 在职 | I25: 23260067 | J25: 魏长生 | M25: 魏长生团队 | N25: 预留团队10 | O25: 云南大区 | P25: 西区团队 | Q25: 1 | R25: 0 | S25: =IFERROR(VLOOKUP(C25,Sheet2!B:E,4,0),C25) -> 一般产品
A26: 652902018110101878 | B26: 1498 | C26: 一般产品 | D26: 海口美兰贝肯通讯商店 | E26: 乌什县时尚一族通信旗舰店 | F26: 01070001 | G26: 奥格莱姆·萨塔尔 | H26: 离职 | I26: 23130064 | J26: 魏明刚 | M26: 魏明刚团队 | N26: 田学文团队 | O26: 新疆大区 | P26: 北区团队 | Q26: 1 | R26: 0 | S26: =IFERROR(VLOOKUP(C26,Sheet2!B:E,4,0),C26) -> 一般产品
A27: 653102018110103558 | B27: 3000 | C27: 一般产品 | D27: 南昌高新技术产业开发区宇恒联合数码产品店 | E27: 叶城县九洲通讯 | F27: 26120379 | G27: 祖丽皮亚·排孜艾合买提 | H27: 在职 | I27: 26250388 | J27: 周燕 | M27: 周燕团队 | N27: 预留(何天浩） | O27: 新疆大区 | P27: 北区团队 | Q27: 1 | R27: 0 | S27: =IFERROR(VLOOKUP(C27,Sheet2!B:E,4,0),C27) -> 一般产品
A28: 522402018110200846 | B28: 3499 | C28: 优惠产品A | D28: 西安高新区兴和电子产品经销部 | E28: 个体户丁六霞 | F28: 03250305 | G28: 陈延平 | H28: 在职 | K28: 26040028 | M28: 预留（朱达松） | N28: 孙雷团队 | O28: 贵州大区 | P28: 西区团队 | Q28: 1 | R28: 0 | S28: =IFERROR(VLOOKUP(C28,Sheet2!B:E,4,0),C28) -> 优惠产品
A29: 653102018110203651 | B29: 2200 | C29: 一般产品 | D29: 南昌高新技术产业开发区宇恒联合数码产品店 | E29: 莎车县广信通手机配件店 | F29: 07240106 | G29: 关新丽 | H29: 在职 | I29: 13180006 | J29: 莫锐 | M29: 莫锐团队 | N29: 邹垚睿团队 | O29: 新疆大区 | P29: 北区团队 | Q29: 1 | R29: 0 | S29: =IFERROR(VLOOKUP(C29,Sheet2!B:E,4,0),C29) -> 一般产品
A30: 653102018110202810 | B30: 5300 | C30: 一般产品 | D30: 海口美兰贝肯通讯商店 | E30: 喀什市金庚初电动车店 | F30: 10250092 | G30: 蒋玉梁 | H30: 在职 | I30: 12190182 | J30: 李仕兴 | M30: 李仕兴团队 | N30: 邹垚睿团队 | O30: 新疆大区 | P30: 北区团队 | Q30: 1 | R30: 0 | S30: =IFERROR(VLOOKUP(C30,Sheet2!B:E,4,0),C30) -> 一般产品
A31: 653102018110403956 | B31: 4200 | C31: 一般产品 | D31: 南昌高新技术产业开发区宇恒联合数码产品店 | E31: 英吉沙县五星钻豹电动车销售部 | F31: 19140011 | G31: 沙尼亚·麦麦提斯迪克 | H31: 在职 | I31: 25110045 | J31: 姚昆 | M31: 姚昆团队 | N31: 邹垚睿团队 | O31: 新疆大区 | P31: 北区团队 | Q31: 1 | R31: 0 | S31: =IFERROR(VLOOKUP(C31,Sheet2!B:E,4,0),C31) -> 一般产品
A32: 540102018110302380 | B32: 3900 | C32: 一般产品 | D32: 汇川区亨乐尔通讯经营部 | E32: 新宇峰数码 | F32: 04250117 | G32: 丁瑶 | H32: 在职 | I32: 26240321 | J32: 郑向阳 | M32: 郑向阳团队 | N32: 预留团队 | O32: 西藏大区 | P32: 直管团队 | Q32: 1 | R32: 0 | S32: =IFERROR(VLOOKUP(C32,Sheet2!B:E,4,0),C32) -> 一般产品
A33: 653002018110103185 | B33: 4000 | C33: 一般产品 | D33: 海口美兰贝肯通讯商店 | E33: 阿图什市若情品牌手机销售店 | F33: 13250102 | G33: 马依拉·阿扎提 | H33: 在职 | I33: 23160051 | J33: 吴鹏飞 | M33: 吴鹏飞团队 | N33: 邹垚睿团队 | O33: 新疆大区 | P33: 北区团队 | Q33: 1 | R33: 0 | S33: =IFERROR(VLOOKUP(C33,Sheet2!B:E,4,0),C33) -> 一般产品
A34: 652902018110103075 | B34: 1500 | C34: 一般产品 | D34: 海口美兰贝肯通讯商店 | E34: 新和县阿布力米提手机销售店 | F34: 11120028 | G34: 卡力比努尔·阿不来提 | H34: 在职 | K34: 08240143 | M34: 预留（韩潇） | N34: 刘香杰团队 | O34: 新疆大区 | P34: 北区团队 | Q34: 1 | R34: 0 | S34: =IFERROR(VLOOKUP(C34,Sheet2!B:E,4,0),C34) -> 一般产品
A35: 653102018110103373 | B35: 2500 | C35: 一般产品 | D35: 南昌高新技术产业开发区宇恒联合数码产品店 | E35: 伽师县吾布力卡斯木阿白克手机销售店 | F35: 07120082 | G35: 古丽努尔·马木提 | H35: 在职 | I35: 04240047 | J35: 邓雪飞 | M35: 邓雪飞团队 | N35: 邹垚睿团队 | O35: 新疆大区 | P35: 北区团队 | Q35: 1 | R35: 0 | S35: =IFERROR(VLOOKUP(C35,Sheet2!B:E,4,0),C35) -> 一般产品
A36: 653102018110202061 | B36: 2300 | C36: 一般产品 | D36: 南昌高新技术产业开发区宇恒联合数码产品店 | E36: 伽师县布拉克手机卖场 | F36: 01260017 | G36: 艾孜提艾力·阿卜杜热合曼 | H36: 离职 | I36: 04240047 | J36: 邓雪飞 | M36: 邓雪飞团队 | N36: 邹垚睿团队 | O36: 新疆大区 | P36: 北区团队 | Q36: 1 | R36: 0 | S36: =IFERROR(VLOOKUP(C36,Sheet2!B:E,4,0),C36) -> 一般产品
A37: 231202018110401409 | B37: 5000 | C37: 优惠产品B | D37: 西宁市城西区雅勤通讯设备经营部 | E37: 华科手机卖场小米 | F37: 23100294 | G37: 吴继鑫 | H37: 在职 | K37: 23240311 | M37: 预留（王小丽） | N37: 预留团队7 | O37: 黑龙江大区 | P37: 北区团队 | Q37: 1 | R37: 0 | S37: =IFERROR(VLOOKUP(C37,Sheet2!B:E,4,0),C37) -> 优惠产品
A38: 654302018110103370 | B38: 3000 | C38: 优惠产品A | D38: 海口美兰贝肯通讯商店 | E38: 郑庆丽（柜台） | F38: 13180027 | G38: 米热依古丽·阿那尔 | H38: 在职 | I38: 23170097 | J38: 王琦 | M38: 王琦团队 | N38: 肖强团队 | O38: 新疆大区 | P38: 北区团队 | Q38: 1 | R38: 0 | S38: =IFERROR(VLOOKUP(C38,Sheet2!B:E,4,0),C38) -> 优惠产品
A39: 653102018110102806 | B39: 3002 | C39: 一般产品 | D39: 海口美兰贝肯通讯商店 | E39: 宏翔通讯 | F39: 13250094 | G39: 穆耶赛尔·阿布都艾尼 | H39: 在职 | I39: 13230011 | J39: 买吾拉尼·吐尔逊 | M39: 买吾拉尼·吐尔逊团队 | N39: 邹垚睿团队 | O39: 新疆大区 | P39: 北区团队 | Q39: 1 | R39: 0 | S39: =IFERROR(VLOOKUP(C39,Sheet2!B:E,4,0),C39) -> 一般产品
A40: 230102018110202044 | B40: 6000 | C40: 优惠产品B | D40: 西宁市城西区雅勤通讯设备经营部 | E40: 羽翔摩托车商店 | F40: 23120219 | G40: 王磊 | H40: 在职 | K40: 12120291 | M40: 预留（吕龙） | N40: 预留团队 | O40: 黑龙江大区 | P40: 北区团队 | Q40: 1 | R40: 0 | S40: =IFERROR(VLOOKUP(C40,Sheet2!B:E,4,0),C40) -> 优惠产品
...

Sheet Sheet2
A1: 渠道 | B1: 产品名称 | C1: 产品编号 | D1: 是否有返点 | E1: 原产品名称 | F1: 产品描述
A2: A01 | B2: 一般产品 | C2: 100003 | D2: 是 | E2: 一般产品
B3: 优惠产品B | C3: 100005 | D3: 是 | E3: 优惠产品
B4: 运营商专享 | C4: 100006 | D4: 是 | E4: 运营商专享
B5: 10期贷A | C5: 100001 | D5: 否 | E5: 10期贷
B6: 一折贷 | C6: 100004 | D6: 否 | E6: 一折贷
B7: 6期购产品A | C7: 100002 | D7: 否 | E7: 6期购产品
A8: A02 | B8: 一般产品 | C8: 100003 | D8: 是 | E8: 一般产品
B9: 优惠产品A | C9: 100007 | D9: 是 | E9: 优惠产品
B10: 运营商专享 | C10: 100006 | D10: 是 | E10: 运营商专享
B11: 10期贷A | C11: 100001 | D11: 否 | E11: 10期贷
B12: 一折贷 | C12: 100004 | D12: 否 | E12: 一折贷
B13: 6期购产品A | C13: 100002 | D13: 否 | E13: 6期购产品
A14: A20 | B14: 009产品A | C14: 100008 | D14: 否 | E14: 009产品
A15: A21 | B15: 10期贷C | C15: 100009 | D15: 是 | E15: 山西10期贷 | F15: 山西-10期贷
A16: A27 | B16: 6期购产品B | C16: 100010 | D16: 是 | E16: 6期购-山西专享 | F16: 山西-6期购
A17: A29 | B17: 003产品 | C17: 100011 | D17: 否 | E17: 003产品
A18: A43 | B18: 优惠购A | C18: 100012 | D18: 是 | E18: 优惠购 | F18: 海南-优惠购
A19: A46 | B19: 优惠购B | C19: 100033 | D19: 是 | E19: 优惠购 | F19: 山西-优惠购
A20: A49 | B20: 灵犀购6 | C20: 100013 | D20: 否 | E20: 灵犀购6 | F20: 海南-灵犀购
B21: 灵犀购9A | C21: 100014 | D21: 否 | E21: 灵犀购9A | F21: 海南-灵犀购
B22: 灵犀购9B | C22: 100015 | D22: 否 | E22: 灵犀购9B | F22: 海南-灵犀购
A23: A54 | B23: 民生通讯129产品 | C23: 100016 | D23: 否 | E23: 民生通讯129产品 | F23: 四川-民生通讯活动产品
B24: 民生通讯198/199产品 | C24: 100017 | D24: 否 | E24: 民生通讯198/199产品 | F24: 四川-民生通讯活动产品
B25: 民生通讯298产品 | C25: 100018 | D25: 否 | E25: 民生通讯298产品 | F25: 四川-民生通讯活动产品
B26: 民生通讯398产品 | C26: 100019 | D26: 否 | E26: 民生通讯398产品 | F26: 四川-民生通讯活动产品
B27: 民生通讯98产品 | C27: 100020 | D27: 否 | E27: 民生通讯98产品 | F27: 四川-民生通讯活动产品
A28: A69 | B28: 民生通讯198/199A | C28: 100025 | D28: 否 | E28: 民生通讯198/199A | F28: 四川-民生通讯活动产品
B29: 民生通讯198B | C29: 100026 | D29: 否 | E29: 民生通讯198B | F29: 四川-民生通讯活动产品
B30: 民生通讯199B | C30: 100027 | D30: 否 | E30: 民生通讯199B | F30: 四川-民生通讯活动产品
B31: 民生通讯398A | C31: 100028 | D31: 否 | E31: 民生通讯398A | F31: 四川-民生通讯活动产品
B32: 民生通讯398B | C32: 100029 | D32: 否 | E32: 民生通讯398B | F32: 四川-民生通讯活动产品
B33: 民生通讯98/99A | C33: 100030 | D33: 否 | E33: 民生通讯98/99A | F33: 四川-民生通讯活动产品
B34: 民生通讯98B | C34: 100031 | D34: 否 | E34: 民生通讯98B | F34: 四川-民生通讯活动产品
B35: 民生通讯99B | C35: 100032 | D35: 否 | E35: 民生通讯99B | F35: 四川-民生通讯活动产品
A36: A61 | B36: 灵犀购9C | C36: 100022 | D36: 否 | E36: 灵犀购9C | F36: 海南-灵犀购
A37: A58 | B37: U客购 | C37: 100021 | D37: 是 | E37: U客购
A38: A62 | B38: 10期贷B | C38: 100023 | D38: 是 | E38: 黑龙江10期贷 | F38: 黑龙江-10期贷
A39: A68 | B39: 黑龙江专享产品 | C39: 100024 | D39: 是 | E39: 黑龙江专享产品
A40: A70 | B40: 读书郎专享 | C40: 100035 | D40: 否 | E40: 读书郎专享
...
